Workbook

Sheet Employee Master
A1: Employee_ID | B1: Employee_Name | C1: Department | D1: Designation | E1: City | F1: Manager_ID | G1: Salary
A2: EMP001 | B2: Amit Sharma | C2: Sales | D2: Executive | E2: Kolkata | F2: MGR101 | G2: 45000
A3: EMP002 | B3: Priya Das | C3: HR | D3: Recruiter | E3: Delhi | F3: MGR102 | G3: 52000
A4: EMP003 | B4: Rahul Roy | C4: Finance | D4: Analyst | E4: Mumbai | F4: MGR103 | G4: 61000
A5: EMP004 | B5: Sneha Ghosh | C5: IT | D5: Developer | E5: Bangalore | F5: MGR104 | G5: 75000
A6: EMP005 | B6: Neha Singh | C6: Marketing | D6: Executive | E6: Pune | F6: MGR105 | G6: 48000
A7: EMP006 | B7: Arjun Sen | C7: Operations | D7: Analyst | E7: Hyderabad | F7: MGR106 | G7: 58000
A8: EMP007 | B8: Rohit Das | C8: Sales | D8: Manager | E8: Kolkata | F8: MGR101 | G8: 82000
A9: EMP008 | B9: Karan Patel | C9: IT | D9: Senior Developer | E9: Bangalore | F9: MGR104 | G9: 96000
A10: EMP009 | B10: Vikram Shah | C10: Finance | D10: Manager | E10: Mumbai | F10: MGR103 | G10: 90000
A11: EMP010 | B11: Anjali Roy | C11: HR | D11: HRBP | E11: Delhi | F11: MGR102 | G11: 78000

Sheet Manager Details
A1: Manager_ID | B1: Manager_Name | C1: Experience | D1: Location
A2: MGR101 | B2: Suman Roy | C2: 12 | D2: Kolkata
A3: MGR102 | B3: Ritu Sharma | C3: 10 | D3: Delhi
A4: MGR103 | B4: Abhishek Jain | C4: 15 | D4: Mumbai
A5: MGR104 | B5: Kunal Mehta | C5: 11 | D5: Bangalore
A6: MGR105 | B6: Meera Das | C6: 9 | D6: Pune
A7: MGR106 | B7: Sanjay Gupta | C7: 13 | D7: Hyderabad

Sheet Quarterly Sales (For HLOOKUP)
A1: Quarter | B1: Q1 | C1: Q2 | D1: Q3 | E1: Q4
A2: Laptop | B2: 120 | C2: 150 | D2: 180 | E2: 170
A3: Mobile | B3: 200 | C3: 240 | D3: 230 | E3: 260
A4: Printer | B4: 80 | C4: 95 | D4: 110 | E4: 105
A5: Monitor | B5: 140 | C5: 150 | D5: 165 | E5: 180

Sheet VLOOKUP
A1: Employee_ID | B1: Employee_Name | C1: Department | D1: Designation | E1: City | F1: Manager_ID | G1: Salary
A2: EMP001 | B2: Amit Sharma | C2: Sales | D2: Executive | E2: Kolkata | F2: MGR101 | G2: 45000
A3: EMP002 | B3: Priya Das | C3: HR | D3: Recruiter | E3: Delhi | F3: MGR102 | G3: 52000
A4: EMP003 | B4: Rahul Roy | C4: Finance | D4: Analyst | E4: Mumbai | F4: MGR103 | G4: 61000
A5: EMP004 | B5: Sneha Ghosh | C5: IT | D5: Developer | E5: Bangalore | F5: MGR104 | G5: 75000
A6: EMP005 | B6: Neha Singh | C6: Marketing | D6: Executive | E6: Pune | F6: MGR105 | G6: 48000
A7: EMP006 | B7: Arjun Sen | C7: Operations | D7: Analyst | E7: Hyderabad | F7: MGR106 | G7: 58000
A8: EMP007 | B8: Rohit Das | C8: Sales | D8: Manager | E8: Kolkata | F8: MGR101 | G8: 82000
A9: EMP008 | B9: Karan Patel | C9: IT | D9: Senior Developer | E9: Bangalore | F9: MGR104 | G9: 96000
A10: EMP009 | B10: Vikram Shah | C10: Finance | D10: Manager | E10: Mumbai | F10: MGR103 | G10: 90000
A11: EMP010 | B11: Anjali Roy | C11: HR | D11: HRBP | E11: Delhi | F11: MGR102 | G11: 78000
A13: Problem 1 | B13: The HR team has only the Employee_ID. Retrieve the Employee_Name.
A14: Answer | B14: =VLOOKUP("EMP005",A2:G11,2,FALSE) -> Neha Singh
A15: Syntax | B15: "=VLOOKUP("EMP005",A2:G11,2,FALSE)"
A16: Problem 2 | B16: Retrieve the Department for every Employee_ID.
A17: Answer | B17: Employee_ID | C17: Department
B18: EMP003 | C18: =VLOOKUP(B18,$A$2:$G$11,3,FALSE) -> Finance
B19: EMP006 | C19: =VLOOKUP(B19,$A$2:$G$11,3,FALSE) -> Operations
B20: EMP010 | C20: =VLOOKUP(B20,$A$2:$G$11,3,FALSE) -> HR
B21: EMP008 | C21: =VLOOKUP(B21,$A$2:$G$11,3,FALSE) -> IT
A22: Syntax | B22: "=VLOOKUP(B18,$A$2:$G$11,3,FALSE)"
A23: Problem 3 | B23: Finance wants the Salary of each employee based on Employee_ID.
A24: Answer | B24: Employee_ID | C24: Salary
B25: EMP003 | C25: =VLOOKUP(B25,$A$2:$G$11,7,FALSE) -> 61000
B26: EMP006 | C26: =VLOOKUP(B26,$A$2:$G$11,7,FALSE) -> 58000
B27: EMP010 | C27: =VLOOKUP(B27,$A$2:$G$11,7,FALSE) -> 78000
B28: EMP008 | C28: =VLOOKUP(B28,$A$2:$G$11,7,FALSE) -> 96000
A29: Syntax | B29: "=VLOOKUP(B25,$A$2:$G$11,7,FALSE)"
A30: Problem 4 | B30: Find the Designation of Employee EMP008.
A31: Answer | B31: =VLOOKUP("EMP008",A2:G11,4,FALSE) -> Senior Developer
A32: Syntax | B32: "=VLOOKUP("EMP008",A2:G11,4,FALSE)"
A33: Problem 5 | B33: Retrieve the City for Employee EMP004.
A34: Answer | B34: =VLOOKUP("EMP004",A2:G11,5,FALSE) -> Bangalore
A35: Syntax | B35: "=VLOOKUP("EMP004",A2:G11,5,FALSE)"

Sheet HLOOKUP
A1: Quarter | B1: Q1 | C1: Q2 | D1: Q3 | E1: Q4
A2: Laptop | B2: 120 | C2: 150 | D2: 180 | E2: 170
A3: Mobile | B3: 200 | C3: 240 | D3: 230 | E3: 260
A4: Printer | B4: 80 | C4: 95 | D4: 110 | E4: 105
A5: Monitor | B5: 140 | C5: 150 | D5: 165 | E5: 180
A7: Problem 1 | B7: Retrieve Q3 sales for Laptop.
A8: Answer | B8: =HLOOKUP("Q3",A1:E5,2,FALSE) -> 180
A9: Syntax | B9: "=HLOOKUP("Q3",A1:E5,2,FALSE)"
A10: Problem 2 | B10: Retrieve Q4 sales for Mobile.
A11: Answer | B11: =HLOOKUP("Q4",A1:E5,3,FALSE) -> 260
A12: Syntax | B12: "=HLOOKUP("Q4",A1:E5,3,FALSE)"
A13: Problem 3 | B13: Retrieve Q2 sales for Printer.
A14: Answer | B14: =HLOOKUP("Q2",A1:E5,4,FALSE) -> 95
A15: Syntax | B15: "=HLOOKUP("Q2",A1:E5,4,FALSE)"
A16: Problem 4 | B16: Retrieve Q1 sales for Monitor.
A17: Answer | B17: =HLOOKUP("Q1",A1:E5,5,FALSE) -> 140
A18: Syntax | B18: "=HLOOKUP("Q1",A1:E5,5,FALSE)"
A19: Problem 5 | B19: Retrieve Q4 sales for Printer.
A20: Answer | B20: =HLOOKUP("Q4",A1:E5,4,FALSE) -> 105
A21: Syntax | B21: "=HLOOKUP("Q4",A1:E5,4,FALSE)"

Sheet XLOOKUP
A1: Employee_ID | B1: Employee_Name | C1: Department | D1: Designation | E1: City | F1: Manager_ID | G1: Salary
A2: EMP001 | B2: Amit Sharma | C2: Sales | D2: Executive | E2: Kolkata | F2: MGR101 | G2: 45000
A3: EMP002 | B3: Priya Das | C3: HR | D3: Recruiter | E3: Delhi | F3: MGR102 | G3: 52000
A4: EMP003 | B4: Rahul Roy | C4: Finance | D4: Analyst | E4: Mumbai | F4: MGR103 | G4: 61000
A5: EMP004 | B5: Sneha Ghosh | C5: IT | D5: Developer | E5: Bangalore | F5: MGR104 | G5: 75000
A6: EMP005 | B6: Neha Singh | C6: Marketing | D6: Executive | E6: Pune | F6: MGR105 | G6: 48000
A7: EMP006 | B7: Arjun Sen | C7: Operations | D7: Analyst | E7: Hyderabad | F7: MGR106 | G7: 58000
A8: EMP007 | B8: Rohit Das | C8: Sales | D8: Manager | E8: Kolkata | F8: MGR101 | G8: 82000
A9: EMP008 | B9: Karan Patel | C9: IT | D9: Senior Developer | E9: Bangalore | F9: MGR104 | G9: 96000
A10: EMP009 | B10: Vikram Shah | C10: Finance | D10: Manager | E10: Mumbai | F10: MGR103 | G10: 90000
A11: EMP010 | B11: Anjali Roy | C11: HR | D11: HRBP | E11: Delhi | F11: MGR102 | G11: 78000
A13: Problem 1 | B13: Retrieve the Salary using Employee_ID.
A14: Answer | B14: =_xlfn.XLOOKUP("EMP003",A2:A11,G2:G11,"Not Found",0) -> 61000
A15: Syntax | B15: "=XLOOKUP("EMP003",A2:A11,G2:G11,"Not Found",0)"
A16: Problem 2 | B16: Retrieve the Department for EMP009.
A17: Answer | B17: =_xlfn.XLOOKUP("EMP009",A2:A11,C2:C11,"Not Found",0) -> Finance
A18: Syntax | B18: "=XLOOKUP("EMP009",A2:A11,C2:C11,"Not Found",0)"
A19: Problem 3 | B19: Return "Employee Not Found" if the Employee_ID doesn't exist.
A20: Answer | B20: =_xlfn.XLOOKUP("EMP012",A2:A11,B2:B11,"Employee Not Found",0) -> Employee Not Found
A21: Syntax | B21: "=XLOOKUP("EMP012",A2:A11,B2:B11,"Employee Not Found",0)"
A22: Problem 4 | B22: Retrieve the Manager_ID using Employee_ID.
A23: Answer | B23: =_xlfn.XLOOKUP("EMP003",A2:A11,F2:F11,"Not Found",0) -> MGR103
A24: Syntax | B24: "=XLOOKUP("EMP003",A2:A11,F2:F11,"Not Found",0)"
A25: Problem 5 | B25: Retrieve Employee_Name for EMP006.
A26: Answer | B26: =_xlfn.XLOOKUP("EMP006",A2:A11,B2:B11,"Not Found",0) -> Arjun Sen
A27: Syntax | B27: "=XLOOKUP("EMP006",A2:A11,B2:B11,"Not Found",0)"

Sheet INDEX-MATCH
A1: Employee_ID | B1: Employee_Name | C1: Department | D1: Designation | E1: City | F1: Manager_ID | G1: Salary
A2: EMP001 | B2: Amit Sharma | C2: Sales | D2: Executive | E2: Kolkata | F2: MGR101 | G2: 45000
A3: EMP002 | B3: Priya Das | C3: HR | D3: Recruiter | E3: Delhi | F3: MGR102 | G3: 52000
A4: EMP003 | B4: Rahul Roy | C4: Finance | D4: Analyst | E4: Mumbai | F4: MGR103 | G4: 61000
A5: EMP004 | B5: Sneha Ghosh | C5: IT | D5: Developer | E5: Bangalore | F5: MGR104 | G5: 75000
A6: EMP005 | B6: Neha Singh | C6: Marketing | D6: Executive | E6: Pune | F6: MGR105 | G6: 48000
A7: EMP006 | B7: Arjun Sen | C7: Operations | D7: Analyst | E7: Hyderabad | F7: MGR106 | G7: 58000
A8: EMP007 | B8: Rohit Das | C8: Sales | D8: Manager | E8: Kolkata | F8: MGR101 | G8: 82000
A9: EMP008 | B9: Karan Patel | C9: IT | D9: Senior Developer | E9: Bangalore | F9: MGR104 | G9: 96000
A10: EMP009 | B10: Vikram Shah | C10: Finance | D10: Manager | E10: Mumbai | F10: MGR103 | G10: 90000
A11: EMP010 | B11: Anjali Roy | C11: HR | D11: HRBP | E11: Delhi | F11: MGR102 | G11: 78000
A13: Problem 1 | B13: Retrieve Salary using Employee_ID.
A14: Answer | B14: =INDEX(G2:G11,MATCH("EMP004",A2:A11,0)) -> 75000
A15: Syntax | B15: "=INDEX(G2:G11,MATCH("EMP004",A2:A11,0))"
A16: Problem 2 | B16: Retrieve Department using Employee_ID.
A17: Answer | B17: =INDEX(C2:C11,MATCH("EMP004",A2:A11,0)) -> IT
A18: Syntax | B18: "=INDEX(C2:C11,MATCH("EMP004",A2:A11,0))"
A19: Problem 3 | B19: Retrieve Designation using Employee_ID.
A20: Answer | B20: =INDEX(D2:D11,MATCH("EMP004",A2:A11,0)) -> Developer
A21: Syntax | B21: "=INDEX(D2:D11,MATCH("EMP004",A2:A11,0))"
A22: Problem 4 | B22: Retrieve City using Employee_ID.
A23: Answer | B23: =INDEX(E2:E11,MATCH("EMP004",A2:A11,0)) -> Bangalore
A24: Syntax | B24: "=INDEX(E2:E11,MATCH("EMP004",A2:A11,0))"
A25: Problem 5 | B25: Retrieve Employee_Name using Employee_ID.
A26: Answer | B26: =INDEX(B2:B11,MATCH("EMP004",A2:A11,0)) -> Sneha Ghosh
A27: Syntax | B27: "=INDEX(B2:B11,MATCH("EMP004",A2:A11,0))"

Sheet Challenge-Problems
A1: Challenge 1 — Manager Lookup
A2: Using Employee Master and Manager Details, retrieve the Manager Name for every employee.
A4: Employee_Name | B4: Manager_ID | C4: Manager_Name
A5: Amit Sharma | B5: MGR101 | C5: =_xlfn.XLOOKUP(B5,'Manager Details'!A:A,'Manager Details'!B:B,"No Manager",0) -> Suman Roy
A6: Priya Das | B6: MGR102 | C6: =_xlfn.XLOOKUP(B6,'Manager Details'!A:A,'Manager Details'!B:B,"No Manager",0) -> Ritu Sharma
A7: Rahul Roy | B7: MGR103 | C7: =_xlfn.XLOOKUP(B7,'Manager Details'!A:A,'Manager Details'!B:B,"No Manager",0) -> Abhishek Jain
A8: Sneha Ghosh | B8: MGR104 | C8: =_xlfn.XLOOKUP(B8,'Manager Details'!A:A,'Manager Details'!B:B,"No Manager",0) -> Kunal Mehta | D8: Syntax :- | E8: "=XLOOKUP(B5,'Manager Details'!A:A,'Manager Details'!B:B,"No Manager",0)"
A9: Neha Singh | B9: MGR105 | C9: =_xlfn.XLOOKUP(B9,'Manager Details'!A:A,'Manager Details'!B:B,"No Manager",0) -> Meera Das
A10: Arjun Sen | B10: MGR106 | C10: =_xlfn.XLOOKUP(B10,'Manager Details'!A:A,'Manager Details'!B:B,"No Manager",0) -> Sanjay Gupta
A11: Rohit Das | B11: MGR101 | C11: =_xlfn.XLOOKUP(B11,'Manager Details'!A:A,'Manager Details'!B:B,"No Manager",0) -> Suman Roy
A12: Karan Patel | B12: MGR104 | C12: =_xlfn.XLOOKUP(B12,'Manager Details'!A:A,'Manager Details'!B:B,"No Manager",0) -> Kunal Mehta
A13: Vikram Shah | B13: MGR103 | C13: =_xlfn.XLOOKUP(B13,'Manager Details'!A:A,'Manager Details'!B:B,"No Manager",0) -> Abhishek Jain
A14: Anjali Roy | B14: MGR102 | C14: =_xlfn.XLOOKUP(B14,'Manager Details'!A:A,'Manager Details'!B:B,"No Manager",0) -> Ritu Sharma
A16: Challenge 2 — Manager Experience
A17: Retrieve the Manager Experience (Years) for each employee.
A19: Employee_Name | B19: Manager_ID | C19: Manager_Exprience
A20: Amit Sharma | B20: MGR101 | C20: =_xlfn.XLOOKUP(B20,'Manager Details'!A:A,'Manager Details'!C:C,0) -> 12
A21: Priya Das | B21: MGR102 | C21: =_xlfn.XLOOKUP(B21,'Manager Details'!A:A,'Manager Details'!C:C,0) -> 10
A22: Rahul Roy | B22: MGR103 | C22: =_xlfn.XLOOKUP(B22,'Manager Details'!A:A,'Manager Details'!C:C,0) -> 15
A23: Sneha Ghosh | B23: MGR104 | C23: =_xlfn.XLOOKUP(B23,'Manager Details'!A:A,'Manager Details'!C:C,0) -> 11 | D23: Syntax :- | E23: "=XLOOKUP(B20,'Manager Details'!A:A,'Manager Details'!C:C,0)"
A24: Neha Singh | B24: MGR105 | C24: =_xlfn.XLOOKUP(B24,'Manager Details'!A:A,'Manager Details'!C:C,0) -> 9
A25: Arjun Sen | B25: MGR106 | C25: =_xlfn.XLOOKUP(B25,'Manager Details'!A:A,'Manager Details'!C:C,0) -> 13
A26: Rohit Das | B26: MGR101 | C26: =_xlfn.XLOOKUP(B26,'Manager Details'!A:A,'Manager Details'!C:C,0) -> 12
A27: Karan Patel | B27: MGR104 | C27: =_xlfn.XLOOKUP(B27,'Manager Details'!A:A,'Manager Details'!C:C,0) -> 11
A28: Vikram Shah | B28: MGR103 | C28: =_xlfn.XLOOKUP(B28,'Manager Details'!A:A,'Manager Details'!C:C,0) -> 15
A29: Anjali Roy | B29: MGR102 | C29: =_xlfn.XLOOKUP(B29,'Manager Details'!A:A,'Manager Details'!C:C,0) -> 10
A32: Challenge 3 — Manager Office Location
A33: Retrieve the Manager's office location using Manager_ID.
A35: Employee_Name | B35: Manager_ID | C35: Manager_Location
A36: Amit Sharma | B36: MGR101 | C36: =_xlfn.XLOOKUP(B36,'Manager Details'!A:A,'Manager Details'!D:D,0) -> Kolkata
A37: Priya Das | B37: MGR102 | C37: =_xlfn.XLOOKUP(B37,'Manager Details'!A:A,'Manager Details'!D:D,0) -> Delhi
A38: Rahul Roy | B38: MGR103 | C38: =_xlfn.XLOOKUP(B38,'Manager Details'!A:A,'Manager Details'!D:D,0) -> Mumbai
A39: Sneha Ghosh | B39: MGR104 | C39: =_xlfn.XLOOKUP(B39,'Manager Details'!A:A,'Manager Details'!D:D,0) -> Bangalore | D39: Syntax | E39: "=XLOOKUP(B35,'Manager Details'!A:A,'Manager Details'!D:D,0)"
A40: Neha Singh | B40: MGR105 | C40: =_xlfn.XLOOKUP(B40,'Manager Details'!A:A,'Manager Details'!D:D,0) -> Pune
A41: Arjun Sen | B41: MGR106 | C41: =_xlfn.XLOOKUP(B41,'Manager Details'!A:A,'Manager Details'!D:D,0) -> Hyderabad
A42: Rohit Das | B42: MGR101 | C42: =_xlfn.XLOOKUP(B42,'Manager Details'!A:A,'Manager Details'!D:D,0) -> Kolkata
A43: Karan Patel | B43: MGR104 | C43: =_xlfn.XLOOKUP(B43,'Manager Details'!A:A,'Manager Details'!D:D,0) -> Bangalore
A44: Vikram Shah | B44: MGR103 | C44: =_xlfn.XLOOKUP(B44,'Manager Details'!A:A,'Manager Details'!D:D,0) -> Mumbai
A45: Anjali Roy | B45: MGR102 | C45: =_xlfn.XLOOKUP(B45,'Manager Details'!A:A,'Manager Details'!D:D,0) -> Delhi
A47: Challenge 4 — Employee Summary
...
